Workbook

Sheet Base Data
A1: TARGET Firm | D1: 1 | H1: 6 | K1: 7 | N1: 8 | Q1: 9 | T1: 10 | W1: 11 | Z1: 12 | AC1: 13 | AF1: 14
B2: ABT US | E2: ISRG US | I2: RGEN US | L2: EW US | O2: TMO US | R2: DHR US | U2: JNJ US | X2: ABBV US | AA2: 6504 JP | AD2: GF SW | AG2: ZWS US | AJ2: CMCO
B3: Abbott Labratories | E3: INTUITIVE SURGICAL INC | I3: Repligen Corp | L3: Edwards Lifesciences Crop | O3: Thermo Fisher Scientific Inc | R3: Danaher Corp | U3: Johnson & Johnson | X3: Abbbvie Inc | AA3: Fuji Electric | AD3: Georg Fischer | AG3: Zurn Water | AJ3: Colum McK
A4: Currency | B4: USD | D4: Currency | E4: USD | H4: Currency | I4: USD | K4: Currency | L4: USD | N4: Currency | O4: USD | Q4: Currency | R4: USD | T4: Currency | U4: USD | W4: Currency | X4: USD | Z4: Currency | AA4: JPY | AC4: Currency | AD4: CHF | AF4: Currency | AG4: USD | AI4: Currency | AJ4: USD
A5: Far Forecast Revenue | B5: 44780.3 | D5: Far Forecast Revenue | E5: 9378.4 | H5: Far Forecast Revenue | I5: 706.2 | K5: Far Forecast Revenue | L5: 6294.1 | N5: Far Forecast Revenue | O5: 45496.5 | Q5: Far Forecast Revenue | R5: 25843.8 | T5: Far Forecast Revenue | U5: 91155.2 | W5: Far Forecast Revenue | X5: 58665 | Z5: Far Forecast Revenue | AA5: 1026 | AC5: Far Forecast Revenue | AD5: 4437 | AF5: Far Forecast Revenue | AG5: 1596 | AI5: Far Forecast Revenue | AJ5: 1059
A6: Far Forecast Date | B6: 46022 | D6: Far Forecast Date | E6: 46022 | H6: Far Forecast Date | I6: 46022 | K6: Far Forecast Date | L6: 45961 | N6: Far Forecast Date | O6: 46022 | Q6: Far Forecast Date | R6: 46022 | T6: Far Forecast Date | U6: 46022 | W6: Far Forecast Date | X6: 46022 | Z6: Far Forecast Date | AA6: 45382 | AC6: Far Forecast Date | AD6: 45746 | AF6: Far Forecast Date | AG6: 45657 | AI6: Far Forecast Date | AJ6: 45746
A7: LTM Revenue | B7: 40725 | D7: LTM Revenue | E7: 7572.5 | H7: LTM Revenue | I7: 602.4 | K7: LTM Revenue | L7: 5999.1 | N7: LTM Revenue | O7: 42364 | Q7: LTM Revenue | R7: 24817 | T7: LTM Revenue | U7: 86576 | W7: LTM Revenue | X7: 55000 | Z7: LTM Revenue | AA7: 959.7 | AC7: LTM Revenue | AD7: 3988 | AF7: LTM Revenue | AG7: 1533 | AI7: LTM Revenue | AJ7: 951
A8: LTM Date | B8: 45473 | D8: LTM Date | E8: 45473 | H8: LTM Date | I8: 45473 | K8: LTM Date | L8: 45473 | N8: LTM Date | O8: 45472 | Q8: LTM Date | R8: 45471 | T8: LTM Date | U8: 45473 | W8: LTM Date | X8: 45473 | Z8: LTM Date | AA8: 44651 | AC8: LTM Date | AD8: 44742 | AF8: LTM Date | AG8: 45107 | AI8: LTM Date | AJ8: 45107
A9: LTM Gross Profit | B9: 22662 | D9: LTM Gross Profit | E9: 5062.7 | H9: LTM Gross Profit | I9: 280.5 | K9: LTM Gross Profit | L9: 4620.9 | N9: LTM Gross Profit | O9: 17416 | Q9: LTM Gross Profit | R9: 14702 | T9: LTM Gross Profit | U9: 60176 | W9: LTM Gross Profit | X9: 34874 | Z9: LTM Gross Profit | AA9: 252 | AC9: LTM Gross Profit | AD9: 2165 | AF9: LTM Gross Profit | AG9: 572 | AI9: LTM Gross Profit | AJ9: 346
A10: LTM EBITDA | B10: 10470 | D10: LTM EBITDA | E10: 2415.6 | H10: LTM EBITDA | I10: 95.5 | K10: LTM EBITDA | L10: 1940.3 | N10: LTM EBITDA | O10: 10817 | Q10: LTM EBITDA | R10: 7769 | T10: LTM EBITDA | U10: 31083 | W10: LTM EBITDA | X10: 27867 | Z10: LTM EBITDA | AA10: 128 | AC10: LTM EBITDA | AD10: 500 | AF10: LTM EBITDA | AG10: 277 | AI10: LTM EBITDA | AJ10: 154
A11: LTM EBIT | B11: 7223 | D11: LTM EBIT | E11: 1962.7 | H11: LTM EBIT | I11: 25 | K11: LTM EBIT | L11: 1759.6 | N11: LTM EBIT | O11: 7498 | Q11: LTM EBIT | R11: 5556 | T11: LTM EBIT | U11: 23814 | W11: LTM EBIT | X11: 19351 | Z11: LTM EBIT | AA11: 85 | AC11: LTM EBIT | AD11: 399 | AF11: LTM EBIT | AG11: 183 | AI11: LTM EBIT | AJ11: 106
A12: LTM OCF | B12: 7900 | D12: LTM OCF | E12: 1662.6 | H12: LTM OCF | I12: 155.2 | K12: LTM OCF | L12: 865.6 | N12: LTM OCF | O12: 9348 | Q12: LTM OCF | R12: 6447 | T12: LTM OCF | U12: 24642 | W12: LTM OCF | X12: 18638 | Z12: LTM OCF | AA12: 116 | AC12: LTM OCF | AD12: 390 | AF12: LTM OCF | AG12: 201 | AI12: LTM OCF | AJ12: 78
A13: LFY FCF | B13: 5059 | D13: LFY FCF | E13: 749.6 | H13: LFY FCF | I13: 77.7 | K13: LFY FCF | L13: 642.8 | N13: LFY FCF | O13: 6927 | Q13: LFY FCF | R13: 5781 | T13: LFY FCF | U13: 18248 | W13: LFY FCF | X13: 22062 | Z13: LFY FCF | AA13: 55 | AC13: LFY FCF | AD13: 217 | AF13: LFY FCF | AG13: 185 | AI13: LFY FCF | AJ13: 63
W14: not everyone reports Gross Profit | AA14: Use most recent available if need be
B15: =B2 -> ABT US | E15: =E2 -> ISRG US | I15: =I2 -> RGEN US | L15: =L2 -> EW US | O15: =O2 -> TMO US | R15: =R2 -> DHR US | U15: =U2 -> JNJ US | X15: =X2 -> ABBV US | AA15: =AA2 -> 6504 JP | AD15: =AD2 -> GF SW | AG15: =AG2 -> ZWS US | AJ15: =AJ2 -> CMCO
A17: Rev Forecast Mo. | B17: =DATEDIF(B8,B6,"m") -> 18 | D17: Rev Forecast Mo. | E17: =DATEDIF(E8,E6,"m") -> 18 | H17: Rev Forecast Mo. | I17: =DATEDIF(I8,I6,"m") -> 18 | K17: Rev Forecast Mo. | L17: =DATEDIF(L8,L6,"m") -> 16 | N17: Rev Forecast Mo. | O17: =DATEDIF(O8,O6,"m") -> 18 | Q17: Rev Forecast Mo. | R17: =DATEDIF(R8,R6,"m") -> 18 | T17: Rev Forecast Mo. | U17: =DATEDIF(U8,U6,"m") -> 18 | W17: Rev Forecast Mo. | X17: =DATEDIF(X8,X6,"m") -> 18 | Z17: Rev Forecast Mo. | AA17: =DATEDIF(AA8,AA6,"m") -> 24 | AC17: Rev Forecast Mo. | AD17: =DATEDIF(AD8,AD6,"m") -> 33 | AF17: Rev Forecast Mo. | AG17: =DATEDIF(AG8,AG6,"m") -> 18 | AI17: Rev Forecast Mo. | AJ17: =DATEDIF(AJ8,AJ6,"m") -> 21
A18: Rev Forecast Yrs. | B18: =B17/12 -> 1.5 | D18: Rev Forecast Yrs. | E18: =E17/12 -> 1.5 | H18: Rev Forecast Yrs. | I18: =I17/12 -> 1.5 | K18: Rev Forecast Yrs. | L18: =L17/12 -> 1.3333333 | N18: Rev Forecast Yrs. | O18: =O17/12 -> 1.5 | Q18: Rev Forecast Yrs. | R18: =R17/12 -> 1.5 | T18: Rev Forecast Yrs. | U18: =U17/12 -> 1.5 | W18: Rev Forecast Yrs. | X18: =X17/12 -> 1.5 | Z18: Rev Forecast Yrs. | AA18: =AA17/12 -> 2 | AC18: Rev Forecast Yrs. | AD18: =AD17/12 -> 2.75 | AF18: Rev Forecast Yrs. | AG18: =AG17/12 -> 1.5 | AI18: Rev Forecast Yrs. | AJ18: =AJ17/12 -> 1.75
B20: =B2 -> ABT US | E20: =E2 -> ISRG US | I20: =I2 -> RGEN US | L20: =L2 -> EW US | O20: =O2 -> TMO US | R20: =R2 -> DHR US | U20: =U2 -> JNJ US | X20: =X2 -> ABBV US | AA20: =AA2 -> 6504 JP | AD20: =AD2 -> GF SW | AG20: =AG2 -> ZWS US | AJ20: =AJ2 -> CMCO
A21: Value Drivers | D21: Value Drivers | H21: Value Drivers | K21: Value Drivers | N21: Value Drivers | Q21: Value Drivers | T21: Value Drivers | W21: Value Drivers
A22: Exp. Rev. Growth | B22: =RATE(B18,0,(B7*(-1)),B5) -> 0.099577655 | D22: Exp. Rev. Growth | E22: =RATE(E18,0,(E7*(-1)),E5) -> 0.23848135 | H22: Exp. Rev. Growth | I22: =RATE(I18,0,(I7*(-1)),I5) -> 0.17231076 | K22: Exp. Rev. Growth | L22: =RATE(L18,0,(L7*(-1)),L5) -> 0.049174043 | N22: Exp. Rev. Growth | O22: =RATE(O18,0,(O7*(-1)),O5) -> 0.073942498 | Q22: Exp. Rev. Growth | R22: =RATE(R18,0,(R7*(-1)),R5) -> 0.041374864 | T22: Exp. Rev. Growth | U22: =RATE(U18,0,(U7*(-1)),U5) -> 0.052892257 | W22: Exp. Rev. Growth | X22: =RATE(X18,0,(X7*(-1)),X5) -> 0.066636364 | Z22: Exp. Rev. Growth | AA22: =RATE(AA18,0,(AA7*(-1)),AA5) -> 0.033965226 | AC22: Exp. Rev. Growth | AD22: =RATE(AD18,0,(AD7*(-1)),AD5) -> 0.054792758 | AF22: Exp. Rev. Growth | AG22: =RATE(AG18,0,(AG7*(-1)),AG5) -> 0.04109589 | AI22: Exp. Rev. Growth | AJ22: =RATE(AJ18,0,(AJ7*(-1)),AJ5) -> 0.11356467
A23: Gross Profit Margin | B23: =B9/B7 -> 0.55646409 | D23: Gross Profit Margin | E23: =E9/E7 -> 0.66856388 | H23: Gross Profit Margin | I23: =I9/I7 -> 0.46563745 | K23: Gross Profit Margin | L23: =L9/L7 -> 0.77026554 | N23: Gross Profit Margin | O23: =O9/O7 -> 0.41110377 | Q23: Gross Profit Margin | R23: =R9/R7 -> 0.59241649 | T23: Gross Profit Margin | U23: =U9/U7 -> 0.69506561 | W23: Gross Profit Margin | X23: =X9/X7 -> 0.63407273 | Z23: Gross Profit Margin | AA23: =AA9/AA7 -> 0.26258206 | AC23: Gross Profit Margin | AD23: =AD9/AD7 -> 0.54287864 | AF23: Gross Profit Margin | AG23: =AG9/AG7 -> 0.37312459 | AI23: Gross Profit Margin | AJ23: =AJ9/AJ7 -> 0.36382755
A24: EBITDA Margin | B24: =B10/B7 -> 0.25709024 | D24: EBITDA Margin | E24: =E10/E7 -> 0.31899637 | H24: EBITDA Margin | I24: =I10/I7 -> 0.15853254 | K24: EBITDA Margin | L24: =L10/L7 -> 0.32343185 | N24: EBITDA Margin | O24: =O10/O7 -> 0.25533472 | Q24: EBITDA Margin | R24: =R10/R7 -> 0.31305154 | T24: EBITDA Margin | U24: =U10/U7 -> 0.3590256 | W24: EBITDA Margin | X24: =X10/X7 -> 0.50667273 | Z24: EBITDA Margin | AA24: =AA10/AA7 -> 0.13337501 | AC24: EBITDA Margin | AD24: =AD10/AD7 -> 0.12537613 | AF24: EBITDA Margin | AG24: =AG10/AG7 -> 0.18069145 | AI24: EBITDA Margin | AJ24: =AJ10/AJ7 -> 0.16193481
A25: EBIT Margin | B25: =B11/B7 -> 0.17736034 | D25: EBIT Margin | E25: =E11/E7 -> 0.25918785 | H25: EBIT Margin | I25: =I11/I7 -> 0.041500664 | K25: EBIT Margin | L25: =L11/L7 -> 0.29331066 | N25: EBIT Margin | O25: =O11/O7 -> 0.1769899 | Q25: EBIT Margin | R25: =R11/R7 -> 0.22387879 | T25: EBIT Margin | U25: =U11/U7 -> 0.27506468 | W25: EBIT Margin | X25: =X11/X7 -> 0.35183636 | Z25: EBIT Margin | AA25: =AA11/AA7 -> 0.088569345 | AC25: EBIT Margin | AD25: =AD11/AD7 -> 0.10005015 | AF25: EBIT Margin | AG25: =AG11/AG7 -> 0.11937378 | AI25: EBIT Margin | AJ25: =AJ11/AJ7 -> 0.11146162
A26: OCF Margin | B26: =B12/B7 -> 0.19398404 | D26: OCF Margin | E26: =E12/E7 -> 0.21955761 | H26: OCF Margin | I26: =I12/I7 -> 0.25763612 | K26: OCF Margin | L26: =L12/L7 -> 0.14428831 | N26: OCF Margin | O26: =O12/O7 -> 0.22065905 | Q26: OCF Margin | R26: =R12/R7 -> 0.2597816 | T26: OCF Margin | U26: =U12/U7 -> 0.28462853 | W26: OCF Margin | X26: =X12/X7 -> 0.33887273 | Z26: OCF Margin | AA26: =AA12/AA7 -> 0.12087111 | AC26: OCF Margin | AD26: =AD12/AD7 -> 0.09779338 | AF26: OCF Margin | AG26: =AG12/AG7 -> 0.13111546 | AI26: OCF Margin | AJ26: =AJ12/AJ7 -> 0.082018927
A27: FCF Margin | B27: =B13/B7 -> 0.12422345 | D27: FCF Margin | E27: =E13/E7 -> 0.098989766 | H27: FCF Margin | I27: =I13/I7 -> 0.12898406 | K27: FCF Margin | L27: =L13/L7 -> 0.10714941 | N27: FCF Margin | O27: =O13/O7 -> 0.16351147 | Q27: FCF Margin | R27: =R13/R7 -> 0.23294516 | T27: FCF Margin | U27: =U13/U7 -> 0.21077435 | W27: FCF Margin | X27: =X13/X7 -> 0.40112727 | Z27: FCF Margin | AA27: =AA13/AA7 -> 0.057309576 | AC27: FCF Margin | AD27: =AD13/AD7 -> 0.05441324 | AF27: FCF Margin | AG27: =AG13/AG7 -> 0.12067841 | AI27: FCF Margin | AJ27: =AJ13/AJ7 -> 0.066246057
E31: .
E32: .
E33: .

Sheet Sort Prep 
A1: a
B2: Value Drivers | C2: ABT US | D2: ISRG US | E2: SYK US | F2: BSX US | G2: MDT US | H2: BDX US | I2: RGEN US | J2: EW US | K2: TMO US | L2: DHR US | M2: JNJ US | N2: ABBV US
B3: Exp. Rev. Growth | C3: 0.065329461 | D3: 0.15325757 | E3: 0.085058275 | F3: 0.12038897 | G3: 0.045102326 | H3: 0.065587461 | I3: 0.11180469 | J3: 0.036658357 | K3: 0.048706643 | L3: 0.027396449 | M3: 0.03495775 | N3: 0.043944932
B4: Gross Profit Margin | C4: 0.55646409 | D4: 0.66856388 | E4: 0.64247978 | F4: 0.70173365 | G4: 0.65515548 | H4: 0.50736332 | I4: 0.46563745 | J4: 0.77026554 | K4: 0.41110377 | L4: 0.59241649 | M4: 0.69506561 | N4: 0.63407273
B5: EBITDA Margin | C5: 0.25709024 | D5: 0.31899637 | E5: 0.27107392 | F5: 0.29069477 | G5: 0.28461798 | H5: 0.35384305 | I5: 0.15853254 | J5: 0.32343185 | K5: 0.25533472 | L5: 0.31305154 | M5: 0.3590256 | N5: 0.50667273
B6: EBIT Margin | C6: 0.17736034 | D6: 0.25918785 | E6: 0.21403525 | F6: 0.21005385 | G6: 0.2036713 | H6: 0.23850111 | I6: 0.041500664 | J6: 0.29331066 | K6: 0.1769899 | L6: 0.22387879 | M6: 0.27506468 | N6: 0.35183636
B7: OCF Margin | C7: 0.19398404 | D7: 0.21955761 | E7: 0.15966151 | F7: 0.17283951 | G7: 0.21174448 | H7: 0.19891063 | I7: 0.25763612 | J7: 0.14428831 | K7: 0.22065905 | L7: 0.2597816 | M7: 0.28462853 | N7: 0.33887273
B8: FCF Margin | C8: 0.12422345 | D8: 0.098989766 | E8: 0.14661742 | F8: 0.11767796 | G8: 0.15962182 | H8: 0.10666734 | I8: 0.12898406 | J8: 0.10714941 | K8: 0.16351147 | L8: 0.23294516 | M8: 0.21077435 | N8: 0.40112727
B10: Value Drivers | C10: DHR US | D10: JNJ US | E10: EW US | F10: ABBV US | G10: MDT US | H10: TMO US | I10: ABT US | J10: BDX US | K10: SYK US | L10: RGEN US | M10: BSX US | N10: ISRG US
B11: Exp. Rev. Growth | C11: 0.027396449 | D11: 0.03495775 | E11: 0.036658357 | F11: 0.043944932 | G11: 0.045102326 | H11: 0.048706643 | I11: 0.065329461 | J11: 0.065587461 | K11: 0.085058275 | L11: 0.11180469 | M11: 0.12038897 | N11: 0.15325757
B13: Value Drivers | C13: TMO US | D13: RGEN US | E13: BDX US | F13: ABT US | G13: DHR US | H13: ABBV US | I13: SYK US | J13: MDT US | K13: ISRG US | L13: JNJ US | M13: BSX US | N13: EW US
B14: Gross Profit Margin | C14: 0.41110377 | D14: 0.46563745 | E14: 0.50736332 | F14: 0.55646409 | G14: 0.59241649 | H14: 0.63407273 | I14: 0.64247978 | J14: 0.65515548 | K14: 0.66856388 | L14: 0.69506561 | M14: 0.70173365 | N14: 0.77026554
B16: Value Drivers | C16: RGEN US | D16: TMO US | E16: ABT US | F16: SYK US | G16: MDT US | H16: BSX US | I16: DHR US | J16: ISRG US | K16: EW US | L16: BDX US | M16: JNJ US | N16: ABBV US
B17: EBITDA Margin | C17: 0.15853254 | D17: 0.25533472 | E17: 0.25709024 | F17: 0.27107392 | G17: 0.28461798 | H17: 0.29069477 | I17: 0.31305154 | J17: 0.31899637 | K17: 0.32343185 | L17: 0.35384305 | M17: 0.3590256 | N17: 0.50667273
B19: Value Drivers | C19: RGEN US | D19: TMO US | E19: ABT US | F19: MDT US | G19: BSX US | H19: SYK US | I19: DHR US | J19: BDX US | K19: ISRG US | L19: JNJ US | M19: EW US | N19: ABBV US
B20: EBIT Margin | C20: 0.041500664 | D20: 0.1769899 | E20: 0.17736034 | F20: 0.2036713 | G20: 0.21005385 | H20: 0.21403525 | I20: 0.22387879 | J20: 0.23850111 | K20: 0.25918785 | L20: 0.27506468 | M20: 0.29331066 | N20: 0.35183636
B22: Value Drivers | C22: EW US | D22: SYK US | E22: BSX US | F22: ABT US | G22: BDX US | H22: MDT US | I22: ISRG US | J22: TMO US | K22: RGEN US | L22: DHR US | M22: JNJ US | N22: ABBV US
B23: OCF Margin | C23: 0.14428831 | D23: 0.15966151 | E23: 0.17283951 | F23: 0.19398404 | G23: 0.19891063 | H23: 0.21174448 | I23: 0.21955761 | J23: 0.22065905 | K23: 0.25763612 | L23: 0.2597816 | M23: 0.28462853 | N23: 0.33887273
B25: Value Drivers | C25: ISRG US | D25: BDX US | E25: EW US | F25: BSX US | G25: ABT US | H25: RGEN US | I25: SYK US | J25: MDT US | K25: TMO US | L25: JNJ US | M25: DHR US | N25: ABBV US
B26: FCF Margin | C26: 0.098989766 | D26: 0.10666734 | E26: 0.10714941 | F26: 0.11767796 | G26: 0.12422345 | H26: 0.12898406 | I26: 0.14661742 | J26: 0.15962182 | K26: 0.16351147 | L26: 0.21077435 | M26: 0.23294516 | N26: 0.40112727
C33: JNJ US | D33: EW US | E33: ISRG US | F33: RGEN US | G33: DHR US | H33: ABBV US | I33: BSX US | J33: BDX US | K33: TMO US | L33: SYK US | M33: MDT US
C34: 0 | D34: 1 | E34: 2 | F34: 2 | G34: 2 | H34: 2 | I34: 4 | J34: 4 | K34: 4 | L34: 5 | M34: 5

Sheet direct + indirect valuation 
C2: P/E | D2: P/BV | E2: P/OCF | F2: P/FCF | G2: EV/S | H2: EV/EBITDA | I2: EV/EBIT
B3: SYK US | C3: 36.02 | D3: 6.89 | E3: 39.77 | F3: 48.45 | G3: 6.87 | H3: 27.05 | I3: 34.73
B4: BSX US | C4: 48.43 | D4: 6.08 | E4: 46.89 | F4: 67.04 | G4: 8.68 | H4: 35.72 | I4: 53.47
B5: MDT US | C5: 21.67 | D5: 2.41 | E5: 17.24 | F5: 23.14 | G5: 4.16 | H5: 17.41 | I5: 26.32
B6: BDX US | C6: 19.56 | D6: 2.7 | E6: 17.77 | F6: 21.76 | G6: 4.23 | H6: 19.01 | I6: 39.48
B7: TMO US | C7: 36.98 | D7: 4.94 | E7: 25.24 | F7: 29.64 | G7: 6.16 | H7: 24.79 | I7: 36.22
B8: Mean | C8: =AVERAGE(C3:C7) -> 32.532 | D8: =AVERAGE(D3:D7) -> 4.604 | E8: =AVERAGE(E3:E7) -> 29.382 | F8: =AVERAGE(F3:F7) -> 38.006 | G8: =AVERAGE(G3:G7) -> 6.02 | H8: =AVERAGE(H3:H7) -> 24.796 | I8: =AVERAGE(I3:I7) -> 38.044
B9: Median | C9: =MEDIAN(C3:C7) -> 36.02 | D9: =MEDIAN(D3:D7) -> 4.94 | E9: =MEDIAN(E3:E7) -> 25.24 | F9: =MEDIAN(F3:F7) -> 29.64 | G9: =MEDIAN(G3:G7) -> 6.16 | H9: =MEDIAN(H3:H7) -> 24.79 | I9: =MEDIAN(I3:I7) -> 36.22
B10: Diff % | C10: =ABS((C8-C9)/C8) -> 0.10721751 | D10: =ABS((D8-D9)/D8) -> 0.072980017 | E10: =ABS((E8-E9)/E8) -> 0.14097066 | F10: =ABS((F8-F9)/F8) -> 0.22012314 | G10: =ABS((G8-G9)/G8) -> 0.023255814 | H10: =ABS((H8-H9)/H8) -> 0.00024197451 | I10: =ABS((I8-I9)/I8) -> 0.047944485
A14: Direct Valuation | J14: Indirect Valuation
A16: =TODAY() -> 46231 | B16: ABT Per Share Data | J16: TARGET Firm
A17: 45473 | B17: 45657 | C17: 46022 | K17: ABT US
A18: 22.6 | B18: 23.44 | C18: 24.34 | D18: Book Value Per Share | K18: Abbott Labratories
A19: =$D$9*A18 -> 111.644 | B19: =$D$9*B18 -> 115.7936 | C19: =$D$9*C18 -> 120.2396 | D19: Estimated Value Using Median P/BV | J19: Currency | K19: USD
J20: Far Forecast Revenue | K20: 44780.3
J21: Far Forecast Date | K21: 46022
J22: LTM Revenue | K22: 40725
J23: LTM Date | K23: 45473
J24: LTM Gross Profit | K24: 22662
J25: LTM EBITDA | K25: 10470
A26: Selected Metric | B26: =D2 -> P/BV | J26: LTM EBIT | K26: 7223
A27: Book Value per share | B27: =A18 -> 22.6 | J27: LTM OCF | K27: 7900
A28: Median Multiple | B28: =D9 -> 4.94 | J28: LFY FCF | K28: 5059
A29: Implied Share Price | B29: =B27*B28 -> 111.644
J30: Metric | K30: EV/EBITDA
J32: ABT EBITDA | K32: =K25 -> 10470
J33: Median Multiple | K33: 24.8
J35: Implied EV | K35: =K32*K33 -> 259656
J36: Less Debt | K36: 14754
J37: Less Preffered | K37: 0
J38: Less minority | K38: 242
J39: Plus Cash | K39: 7547
J41: Implied Equity Value | K41: =K35-K36-K37-K38+K39 -> 252207
J43: Number of shares | K43: 1739.9
J45: Implied Share Price | K45: =K41/K43 -> 144.95488

Sheet Historical Percentages ABT
B1: Enterprise Valuation Based DCF
B2: Historical Percentages: Abbott Laboratories | C2: 2020 | D2: 2021 | E2: 2022 | F2: 2023 | G2: Current
G3: 6/30/2024
B4: Sales | C4: 34608 | D4: 43075 | E4: 43653 | F4: 40109 | G4: 40725
B5: % Sales Growth | D5: =((D4/C4)-1) -> 0.24465442 | E5: =((E4/D4)-1) -> 0.013418456 | F5: =((F4/E4)-1) -> -0.081185715 | G5: =((G4/F4)-1) -> 0.015358149
B7: EBITDA | C7: 9621 | D7: 13149 | E7: 12895 | F7: 10519 | G7: 10470
B8: EBITDA Margin | C8: =C7/C4 -> 0.27799931 | D8: =D7/D4 -> 0.30525827 | E8: =E7/E4 -> 0.2953978 | F8: =F7/F4 -> 0.26226034 | G8: =G7/G4 -> 0.25709024
B10: Depreciation and Amortization | C10: 3327 | D10: 3538 | E10: 3267 | F10: 3243 | G10: 3247
C11: =C10/C4 -> 0.096133842 | D11: =D10/D4 -> 0.08213581 | E11: =E10/E4 -> 0.074840217 | F11: =F10/F4 -> 0.080854671 | G11: =G10/G4 -> 0.079729896
B12: EBIT | C12: =C7-C10 -> 6294 | D12: =D7-D10 -> 9611 | E12: =E7-E10 -> 9628 | F12: =F7-F10 -> 7276 | G12: =G7-G10 -> 7223
B13: EBIT Margin | C13: =C12/C4 -> 0.18186546 | D13: =D12/D4 -> 0.22312246 | E13: =E12/E4 -> 0.22055758 | F13: =F12/F4 -> 0.18140567 | G13: =G12/G4 -> 0.17736034
B15: Taxes | C15: 497 | D15: 1140 | E15: 1373 | F15: 941 | G15: 952
B16: Tax Rate | C16: =C15/C12 -> 0.078964093 | D16: =D15/D12 -> 0.11861409 | E16: =E15/E12 -> 0.1426049 | F16: =F15/F12 -> 0.1293293 | G16: =G15/G12 -> 0.13180119
B18: EBIAT | C18: =C12-C15 -> 5797 | D18: =D12-D15 -> 8471 | E18: =E12-E15 -> 8255 | F18: =F12-F15 -> 6335 | G18: =G12-G15 -> 6271
B20: Depreciation and Amortization | C20: =C10 -> 3327 | D20: =D10 -> 3538 | E20: =E10 -> 3267 | F20: =F10 -> 3243 | G20: =G10 -> 3247
B21: D&A/Sales | C21: =C10/C4 -> 0.096133842 | D21: =D10/D4 -> 0.08213581 | E21: =E10/E4 -> 0.074840217 | F21: =F10/F4 -> 0.080854671 | G21: =G10/G4 -> 0.079729896
B23: Capex | C23: -2177 | D23: -1885 | E23: -1777 | F23: -2202 | G23: -2246
B24: Capex/Sales | C24: =C23/C4 -> -0.062904531 | D24: =D23/D4 -> -0.043760882 | E24: =E23/E4 -> -0.040707397 | F24: =F23/F4 -> -0.054900396 | G24: =G23/G4 -> -0.055150399
B26: Less Increase (or Plus Decrease) in NWC | C26: -892 | D26: -771 | E26: -1519 | F26: -2475 | G26: -1706
B27: NWC/Sales | C27: =C26/C4 -> -0.025774387 | D27: =D26/D4 -> -0.017899013 | E27: =E26/E4 -> -0.03479715 | F27: =F26/F4 -> -0.061706849 | G27: =G26/G4 -> -0.041890731

Sheet DCF Valuation (2)
B1: Abbott Labs DCF | C1: Current - 06/30/2024
H2: 2028
B3: Operating Scenario | C3: 2023 | D3: 2024E | E3: 2025E | F3: 2026E | G3: 2027E | H3: 2028E
B4: Sales | C4: ='Historical Percentages ABT'!F4 -> 40109 | D4: =(1+D5)*C4 -> 42114.45 | E4: =(1+E5)*D4 -> 45483.606 | F4: =(1+F5)*E4 -> 47757.786 | G4: =(1+G5)*F4 -> 49190.52 | H4: =(1+H5)*G4 -> 50174.33
B5: % Sales Growth | C5: ='Historical Percentages ABT'!F5 -> -0.081185715 | D5: 0.05 | E5: 0.08 | F5: 0.05 | G5: 0.03 | H5: 0.02
B7: EBITDA | C7: ='Historical Percentages ABT'!F7 -> 10519 | D7: =D8*D4 -> 10949.757 | E7: =E8*E4 -> 12280.574 | F7: =F8*F4 -> 12894.602 | G7: =G8*G4 -> 13281.44 | H7: =H8*H4 -> 13547.069
B8: EBITDA Margin | C8: =C7/C4 -> 0.26226034 | D8: 0.26 | E8: 0.27 | F8: 0.27 | G8: 0.27 | H8: 0.27
B10: Depreciation and Amortization* | C10: ='Historical Percentages ABT'!F10 -> 3243 | D10: =D11*D4 -> 3495.4994 | E10: =E11*E4 -> 3775.1393 | F10: =F11*F4 -> 3963.8963 | G10: =G11*G4 -> 4082.8132 | H10: =H11*H4 -> 4164.4694
B11: D&A/Sales | C11: =C10/C4 -> 0.080854671 | D11: 0.083 | E11: 0.083 | F11: 0.083 | G11: 0.083 | H11: 0.083
B13: EBIT | C13: =C7-C10 -> 7276 | D13: =D7-D10 -> 7454.2576 | E13: =E7-E10 -> 8505.4343 | F13: =F7-F10 -> 8930.706 | G13: =G7-G10 -> 9198.6272 | H13: =H7-H10 -> 9382.5998
B14: EBIT Margin | C14: =C13/C4 -> 0.18140567 | D14: 0.17 | E14: 0.18 | F14: 0.19 | G14: 0.2 | H14: 0.21
B16: Taxes | C16: ='Historical Percentages ABT'!F15 -> 941 | D16: =D17*D13 -> 1118.1386 | E16: =E17*E13 -> 1275.8151 | F16: =F17*F13 -> 1339.6059 | G16: =G17*G13 -> 1379.7941 | H16: =H17*H13 -> 1407.39
B17: Tax Rate | C17: =C16/C13 -> 0.1293293 | D17: 0.15 | E17: 0.15 | F17: 0.15 | G17: 0.15 | H17: 0.15
B19: Unlevered Free Cash Flow | C19: 2023 | D19: 2024E | E19: 2025E | F19: 2026E | G19: 2027E | H19: 2028E
B21: EBIAT | C21: =C13-C16 -> 6335 | D21: =D13-D16 -> 6336.119 | E21: =E13-E16 -> 7229.6192 | F21: =F13-F16 -> 7591.1001 | G21: =G13-G16 -> 7818.8331 | H21: =H13-H16 -> 7975.2098
B23: Depreciation and Amortization* | C23: =C10 -> 3243 | D23: =D10 -> 3495.4994 | E23: =E10 -> 3775.1393 | F23: =F10 -> 3963.8963 | G23: =G10 -> 4082.8132 | H23: =H10 -> 4164.4694
B24: D&A/Sales | C24: =C10/C4 -> 0.080854671 | D24: =D10/D4 -> 0.083 | E24: =E10/E4 -> 0.083 | F24: =F10/F4 -> 0.083 | G24: =G10/G4 -> 0.083 | H24: =H10/H4 -> 0.083
B26: Capex | C26: ='Historical Percentages ABT'!F23 -> -2202 | D26: =D27*D4 -> -2526.867 | E26: =E27*E4 -> -2638.0491 | F26: =F27*F4 -> -2722.1938 | G26: =G27*G4 -> -2607.0976 | H26: =H27*H4 -> -2006.9732
B27: Capex/Sales | C27: =C26/C4 -> -0.054900396 | D27: -0.06 | E27: -0.058 | F27: -0.057 | G27: -0.053 | H27: -0.04
B29: Less Increase (or Plus Decrease) in NWC** | C29: ='Historical Percentages ABT'!F26 -> -2475 | D29: =D30*D4 -> -1895.1502 | E29: =E30*E4 -> -2046.7623 | F29: =F30*F4 -> -477.57786 | G29: =G30*G4 -> -491.9052 | H29: =H30*H4 -> -501.7433
B30: NWC/Sales | C30: =C29/C4 -> -0.061706849 | D30: -0.045 | E30: -0.045 | F30: -0.01 | G30: -0.01 | H30: -0.01
B32: Unlevered Free Cash Flow to the Firm | D32: =D21+D23+D26+D29 -> 5409.6011 | E32: =E21+E23+E26+E29 -> 6319.9471 | F32: =F21+F23+F26+F29 -> 8355.2247 | G32: =G21+G23+G26+G29 -> 8802.6435 | H32: =H21+H23+H26+H29 -> 9630.9627
B34: Discounting of Annual Free Cash Flow | C34: 2023 | D34: 2024E | E34: 2025E | F34: 2026E | G34: 2027E | H34: 2028E
B36: Discount Period (Mid-Year Convention) | D36: 0.5 | E36: 1.5 | F36: 2.5 | G36: 3.5 | H36: 4.5
B38: WACC | D38: 0.082 | E38: =D38 -> 0.082 | F38: =E38 -> 0.082 | G38: =F38 -> 0.082 | H38: =G38 -> 0.082
B40: PVLS Factor | D40: =(1/((1+D38)^D36)) -> 0.96136071 | E40: =(1/((1+E38)^E36)) -> 0.88850343 | F40: =(1/((1+F38)^F36)) -> 0.82116768 | G40: =(1/((1+G38)^G36)) -> 0.75893501 | H40: =(1/((1+H38)^H36)) -> 0.70141868
B42: Present Value of Free Cash Flow | D42: =D40*D32 -> 5200.578 | E42: =E40*E32 -> 5615.2946 | F42: =F40*F32 -> 6861.0405 | G42: =G40*G32 -> 6680.6344 | H42: =H40*H32 -> 6755.3371
E44: Terminal (Continuing) Value
E46: Exit Year Sales | H46: =H7 -> 13547.069
E48: Exit Multiple EV/EBITDA | H48: 11.8
E50: Terminal Value | H50: =H46*H48 -> 159855.42
E52: Discount Factor | H52: =((1/((1+H38)^(H2-C3)))) -> 0.67431636
E55: Implied "g" | H55: =((H50*D38)-(H32*((1+D38)^0.5)))/(H50+(H32*((1+D38)^0.5))) -> 0.018190545
B57: Enterprise Value:
B59: Cumulative Present Value of Unlevered Free Cash Flow to the Firm | C59: =SUM(D42:H42) -> 31112.885
B61: Present Value of Terminal Value | C61: =(H50*H52) -> 107793.12
B62: % of Enterprise Value | C62: =C61/C64 -> 0.77601484
B64: Enterprise Value | C64: =C59+C61 -> 138906.01
B66: Implied Equity Value
B68: Enterprise Value | C68: =C64 -> 138906.01
...

Sheet Final Recommendation
B3: Final Target Price
B4: Method | C4: Target | D4: Weight
B5: Direct | C5: ='direct + indirect valuation '!B29 -> 111.644 | D5: 0.25
B6: Indirect | C6: ='direct + indirect valuation '!K45 -> 144.95488 | D6: 0.25
B7: DCF | C7: ='DCF Valuation (2)'!C82 -> 114.91523 | D7: 0.5
B9: Target | C9: =SUMPRODUCT(C5:C7,D5:D7) -> 121.60734 | D9: =SUM(D5:D7) -> 1
